ERROR | 2022-10-07 12:18:51,756 | main.py:37 | BOT WAS STARTED
NoneType: None
ERROR | 2022-10-07 14:15:16,418 | dispatcher.py:390 | Cause exception while getting updates.
Traceback (most recent call last):
  File "/home/niko/Documents/EBilim-v2/venv/lib/python3.10/site-packages/aiogram/dispatcher/dispatcher.py", line 381, in start_polling
    updates = await self.bot.get_updates(
  File "/home/niko/Documents/EBilim-v2/venv/lib/python3.10/site-packages/aiogram/bot/bot.py", line 110, in get_updates
    result = await self.request(api.Methods.GET_UPDATES, payload)
  File "/home/niko/Documents/EBilim-v2/venv/lib/python3.10/site-packages/aiogram/bot/base.py", line 236, in request
    return await api.make_request(await self.get_session(), self.server, self.__token, method, data, files,
  File "/home/niko/Documents/EBilim-v2/venv/lib/python3.10/site-packages/aiogram/bot/api.py", line 139, in make_request
    async with session.post(url, data=req, **kwargs) as response:
  File "/home/niko/Documents/EBilim-v2/venv/lib/python3.10/site-packages/aiohttp/client.py", line 1141, in __aenter__
    self._resp = await self._coro
  File "/home/niko/Documents/EBilim-v2/venv/lib/python3.10/site-packages/aiohttp/client.py", line 560, in _request
    await resp.start(conn)
  File "/home/niko/Documents/EBilim-v2/venv/lib/python3.10/site-packages/aiohttp/client_reqrep.py", line 894, in start
    with self._timer:
  File "/home/niko/Documents/EBilim-v2/venv/lib/python3.10/site-packages/aiohttp/helpers.py", line 720, in __exit__
    raise asyncio.TimeoutError from None
asyncio.exceptions.TimeoutError
ERROR | 2022-10-07 18:24:51,115 | dispatcher.py:390 | Cause exception while getting updates.
Traceback (most recent call last):
  File "/home/niko/Documents/EBilim-v2/venv/lib/python3.10/site-packages/aiogram/dispatcher/dispatcher.py", line 381, in start_polling
    updates = await self.bot.get_updates(
  File "/home/niko/Documents/EBilim-v2/venv/lib/python3.10/site-packages/aiogram/bot/bot.py", line 110, in get_updates
    result = await self.request(api.Methods.GET_UPDATES, payload)
  File "/home/niko/Documents/EBilim-v2/venv/lib/python3.10/site-packages/aiogram/bot/base.py", line 236, in request
    return await api.make_request(await self.get_session(), self.server, self.__token, method, data, files,
  File "/home/niko/Documents/EBilim-v2/venv/lib/python3.10/site-packages/aiogram/bot/api.py", line 139, in make_request
    async with session.post(url, data=req, **kwargs) as response:
  File "/home/niko/Documents/EBilim-v2/venv/lib/python3.10/site-packages/aiohttp/client.py", line 1141, in __aenter__
    self._resp = await self._coro
  File "/home/niko/Documents/EBilim-v2/venv/lib/python3.10/site-packages/aiohttp/client.py", line 560, in _request
    await resp.start(conn)
  File "/home/niko/Documents/EBilim-v2/venv/lib/python3.10/site-packages/aiohttp/client_reqrep.py", line 894, in start
    with self._timer:
  File "/home/niko/Documents/EBilim-v2/venv/lib/python3.10/site-packages/aiohttp/helpers.py", line 720, in __exit__
    raise asyncio.TimeoutError from None
asyncio.exceptions.TimeoutError
WARNING | 2022-10-07 18:25:07,257 | executor.py:329 | Goodbye!
